Workbook

Sheet Assumptions
A1: V2X, Inc. (NYSE: VVX) — LBO Model: Assumptions
A2: All inputs in blue. $ in 000s unless noted. Change any blue cell to flex the model.
A4: Transaction Assumptions
A5: Entry / close date | B5: 12/31/2025
A6: Entry TEV / EBITDA multiple | B6: 11 | G6: 11.0x = KBR/LinQuest precedent (11.0x); modest premium to VVX undisturbed trading multiple (~10.5x, see Market Reference below); within Perspecta/Veritas comp range of 10.5x-13.3x (Perspecta DEFM14A)
A7: Transaction fees (% of entry TEV) | B7: 0.015
A8: Financing fees (% of new debt raised) | B8: 0.025
A9: Minimum cash balance funded at close | B9: 50000
A10: Hold period (years) | B10: 5
A11: Exit year | B11: 2030
A12: Exit TEV / EBITDA multiple | B12: 11 | G12: Base case assumes flat multiple (no re-rating); return relies on EBITDA growth + deleveraging. Flexed in Sensitivities.
A14: Financing Structure at Close
A15: New Term Loan B (x Entry EBITDA) | B15: 4.5
A16: New Senior Notes (x Entry EBITDA) | B16: 1.5
A17: Revolver capacity | B17: 150000
A18: Term Loan B interest rate (all-in) | B18: 0.07 | G18: vs. 6.50% effective rate on V2X's actual First Lien TLB at 12/31/25 (10-K Note DEBT); wider spread assumed for higher LBO leverage
A19: Senior Notes interest rate (fixed) | B19: 0.085
A20: Revolver interest rate (all-in, if drawn) | B20: 0.0725
A21: Revolver commitment fee (undrawn) | B21: 0.00375 | G21: V2X's actual 2025 Revolver unused fee is 0.25%-0.375% depending on leverage (10-K Note DEBT)
A22: Term Loan B mandatory amortization (% of orig. principal, p.a.) | B22: 0.01
A23: Cash flow sweep % (of FCF after mandatory amort.) | B23: 0.75
A25: Operating Assumptions — Revenue Growth & EBITDA Margin Path
B26: FY2026 | C26: FY2027 | D26: FY2028 | E26: FY2029 | F26: FY2030
A27: Revenue growth % | B27: 0.04 | C27: 0.04 | D27: 0.045 | E27: 0.045 | F27: 0.045
A28: EBITDA margin % | B28: 0.07 | C28: 0.072 | D28: 0.074 | E28: 0.075 | F28: 0.076
A30: Operating Assumptions — Flat Rates
A31: D&A (% of revenue) | B31: 0.024 | G31: vs. FY25A actual D&A/revenue of 2.51% (10-K cash flow statement)
A32: Capex (% of revenue) | B32: 0.0035 | G32: vs. FY23A-FY25A actual capex/revenue of 0.27%-0.63% (10-K cash flow statements)
A33: Net working capital (% of revenue) | B33: -0.03 | G33: Negative NWC is a source of cash as revenue grows; vs. FY25A actual of -3.00% of revenue (see Historical Financials tab)
A34: Cash tax rate | B34: 0.25 | G34: vs. FY25A effective rate of 22.8% (10-K income statement); rounded up as a normalized go-forward estimate
A36: Market Reference (informational — not used in calc-tab formulas)
A37: VVX stock price | B37: 79.01 | G37: stockanalysis.com quote, 2026-08-20 close
A38: Shares outstanding (000s) | B38: 31350 | G38: stockanalysis.com, 2026-08-20
A39: Implied current market capitalization | B39: =B37*B38
A40: Existing net debt at 12/31/2025 (principal basis) | B40: ='Historical Financials'!B62
A41: Implied current trading TEV | B41: =B39+B40
A42: Implied current trading TEV / FY25A EBITDA | B42: =B41/'Historical Financials'!B63

Sheet Historical Financials
A1: V2X, Inc. (NYSE: VVX) — Historical Financials
A2: $ in 000s unless noted. Every figure traces to a 10-K per the Source column.
A4: Filing references used below:
A5: 10-K FY2025 (period ended 12/31/2025, filed 2026-02-23), SEC accession 0001601548-26-000015
A6: 10-K FY2023 (period ended 12/31/2023, filed 2024-03-05), SEC accession 0001601548-24-000004
A8: Consolidated Statements of Income (Loss) ($000s)
B9: FY2021 | C9: FY2022 | D9: FY2023 | E9: FY2024 | F9: FY2025 | H9: Source
A10: Revenue | B10: 1783665 | C10: 2890860 | D10: 3963126 | E10: 4322155 | F10: 4480038 | H10: 10-K FY2025 Consolidated Statements of Income (Loss), FY23-25 cols; 10-K FY2023 Consolidated Statements of (Loss) Income, FY21-23 cols
A11: Cost of revenue | B11: 1623245 | C11: 2595848 | D11: 3628271 | E11: 3979193 | F11: 4106656 | H11: 10-K FY2025 Consolidated Statements of Income (Loss), FY23-25 cols; 10-K FY2023 Consolidated Statements of (Loss) Income, FY21-23 cols
A12: Selling, general & administrative | B12: 98400 | C12: 239241 | D12: 210439 | E12: 183758 | F12: 179112 | H12: 10-K FY2025 Consolidated Statements of Income (Loss), FY23-25 cols; 10-K FY2023 Consolidated Statements of (Loss) Income, FY21-23 cols
A13: Operating income | B13: 62020 | C13: 55771 | D13: 124416 | E13: 159204 | F13: 194270 | H13: 10-K FY2025 Consolidated Statements of Income (Loss), FY23-25 cols; 10-K FY2023 Consolidated Statements of (Loss) Income, FY21-23 cols
A14: Loss on extinguishment of debt | B14: 0 | C14: 0 | D14: -22298 | E14: -1998 | F14: -2527 | H14: 10-K FY2025 Consolidated Statements of Income (Loss), FY23-25 cols; 10-K FY2023 Consolidated Statements of (Loss) Income, FY21-23 cols
A15: Interest expense, net | B15: -7985 | C15: -61879 | D15: -122442 | E15: -107900 | F15: -79909 | H15: 10-K FY2025 Consolidated Statements of Income (Loss), FY23-25 cols; 10-K FY2023 Consolidated Statements of (Loss) Income, FY21-23 cols
A16: Other expense, net | B16: 0 | C16: 0 | D16: -4194 | E16: -10465 | F16: -10931 | H16: 10-K FY2025 Consolidated Statements of Income (Loss), FY23-25 cols; 10-K FY2023 Consolidated Statements of (Loss) Income, FY21-23 cols
A17: Pretax income (loss) | B17: 54035 | C17: -6108 | D17: -24518 | E17: 38841 | F17: 100903 | H17: 10-K FY2025 Consolidated Statements of Income (Loss), FY23-25 cols; 10-K FY2023 Consolidated Statements of (Loss) Income, FY21-23 cols
A18: Income tax expense (benefit) | B18: 8307 | C18: 8222 | D18: -1945 | E18: 4157 | F18: 23021 | H18: 10-K FY2025 Consolidated Statements of Income (Loss), FY23-25 cols; 10-K FY2023 Consolidated Statements of (Loss) Income, FY21-23 cols
A19: Net income (loss) | B19: 45728 | C19: -14330 | D19: -22573 | E19: 34684 | F19: 77882 | H19: 10-K FY2025 Consolidated Statements of Income (Loss), FY23-25 cols; 10-K FY2023 Consolidated Statements of (Loss) Income, FY21-23 cols
A21: Consolidated Balance Sheets ($000s)
C22: FY2022 | D22: FY2023 | E22: FY2024 | F22: FY2025 | H22: Source
A23: Cash, cash equivalents & restricted cash | C23: 116067 | D23: 72651 | E23: 268321 | F23: 368994 | H23: 10-K FY2025 Consolidated Balance Sheets, FY24-25 cols; 10-K FY2023 Consolidated Balance Sheets, FY22-23 cols
A24: Receivables | C24: 728582 | D24: 705995 | E24: 710068 | F24: 738922 | H24: 10-K FY2025 Consolidated Balance Sheets, FY24-25 cols; 10-K FY2023 Consolidated Balance Sheets, FY22-23 cols
A25: Prepaid & other current assets (incl. inventory FY22-23) | C25: 87283 | D25: 96223 | E25: 124081 | F25: 127102 | H25: 10-K FY2025 Consolidated Balance Sheets, FY24-25 cols; 10-K FY2023 Consolidated Balance Sheets, FY22-23 cols
A26: Total current assets | C26: 931932 | D26: 874869 | E26: 1102470 | F26: 1235018 | H26: 10-K FY2025 Consolidated Balance Sheets, FY24-25 cols; 10-K FY2023 Consolidated Balance Sheets, FY22-23 cols
A27: Property, plant & equipment, net | C27: 78715 | D27: 85429 | E27: 62001 | F27: 52383 | H27: 10-K FY2025 Consolidated Balance Sheets, FY24-25 cols; 10-K FY2023 Consolidated Balance Sheets, FY22-23 cols
A28: Goodwill | C28: 1653822 | D28: 1656926 | E28: 1656926 | F28: 1677154 | H28: 10-K FY2025 Consolidated Balance Sheets, FY24-25 cols; 10-K FY2023 Consolidated Balance Sheets, FY22-23 cols
A29: Intangible assets, net | C29: 497951 | D29: 407530 | E29: 323068 | F29: 239760 | H29: 10-K FY2025 Consolidated Balance Sheets, FY24-25 cols; 10-K FY2023 Consolidated Balance Sheets, FY22-23 cols
A30: Other non-current assets (incl. ROU FY22-23) | C30: 70683 | D30: 57146 | E30: 84378 | F30: 76525 | H30: 10-K FY2025 Consolidated Balance Sheets, FY24-25 cols; 10-K FY2023 Consolidated Balance Sheets, FY22-23 cols
A31: Total assets | C31: 3233103 | D31: 3081900 | E31: 3228843 | F31: 3280840 | H31: 10-K FY2025 Consolidated Balance Sheets, FY24-25 cols; 10-K FY2023 Consolidated Balance Sheets, FY22-23 cols
A32: Accounts payable | C32: 406706 | D32: 453052 | E32: 547568 | F32: 557042 | H32: 10-K FY2025 Consolidated Balance Sheets, FY24-25 cols; 10-K FY2023 Consolidated Balance Sheets, FY22-23 cols
A33: Compensation & other employee benefits | C33: 168038 | D33: 158088 | E33: 166918 | F33: 176530 | H33: 10-K FY2025 Consolidated Balance Sheets, FY24-25 cols; 10-K FY2023 Consolidated Balance Sheets, FY22-23 cols
A34: Short-term debt | C34: 11850 | D34: 15361 | E34: 20003 | F34: 14935 | H34: 10-K FY2025 Consolidated Balance Sheets, FY24-25 cols; 10-K FY2023 Consolidated Balance Sheets, FY22-23 cols
... A41: Total shareholders' equity | C41: 997079 | D41: 990800 | E41: 1026152 | F41: 1084636 | H41: 10-K FY2025 Consolidated Balance Sheets, FY24-25 cols; 10-K FY2023 Consolidated Balance Sheets, FY22-23 cols
A42: Balance check (Assets − Liabilities − Equity, should = 0) | C42: =C31-C40-C41 | D42: =D31-D40-D41 | E42: =E31-E40-E41 | F42: =F31-F40-F41
A44: Consolidated Statements of Cash Flows ($000s)
B45: FY2021 | C45: FY2022 | D45: FY2023 | E45: FY2024 | F45: FY2025 | H45: Source
A46: Depreciation expense | B46: 6526 | C46: 13472 | D46: 22408 | E46: 20747 | F46: 16984 | H46: 10-K FY2025 Consolidated Statements of Cash Flows, FY23-25 cols; 10-K FY2023 Consolidated Statements of Cash Flows, FY21-23 cols
A47: Amortization of intangible assets | B47: 10028 | C47: 48643 | D47: 90423 | E47: 90821 | F47: 90621 | H47: 10-K FY2025 Consolidated Statements of Cash Flows, FY23-25 cols; 10-K FY2023 Consolidated Statements of Cash Flows, FY21-23 cols
A48: Amortization of cloud computing arrangements | B48: 0 | C48: 0 | D48: 480 | E48: 3314 | F48: 4919 | H48: 10-K FY2025 Consolidated Statements of Cash Flows, FY23-25 cols; 10-K FY2023 Consolidated Statements of Cash Flows, FY21-23 cols
A49: Capital expenditures (purchases of capital assets & intangibles) | B49: 9776 | C49: 12425 | D49: 25021 | E49: 11787 | F49: 11923 | H49: 10-K FY2025 Consolidated Statements of Cash Flows, FY23-25 cols; 10-K FY2023 Consolidated Statements of Cash Flows, FY21-23 cols
A50: Net cash provided by operating activities | B50: 61339 | C50: 93495 | D50: 187968 | E50: 254237 | F50: 181992 | H50: 10-K FY2025 Consolidated Statements of Cash Flows, FY23-25 cols; 10-K FY2023 Consolidated Statements of Cash Flows, FY21-23 cols
...

Sheet Sources & Uses
A1: V2X, Inc. (NYSE: VVX) — Sources & Uses
A2: $ in millions. All cells are formulas referencing the Assumptions and Historical Financials tabs.
A4: Transaction Value
A5: Entry EBITDA (FY2025A) | B5: ='Historical Financials'!B63/1000
A6: Entry TEV / EBITDA multiple | B6: =Assumptions!B6
A7: Entry TEV | B7: =B5*B6
A8: Less: existing net debt (principal basis) | B8: ='Historical Financials'!B62/1000
A9: Equity purchase price | B9: =B7-B8
A11: Financing Structure (computed here, used throughout model)
A12: New Term Loan B | B12: =B5*Assumptions!B15
A13: New Senior Notes | B13: =B5*Assumptions!B16
A14: Total new debt raised | B14: =B12+B13
A15: Total new debt / Entry EBITDA | B15: =B14/B5
A17: Uses
A18: Equity purchase price | B18: =B9
A19: Refinance existing debt (gross principal) | B19: ='Historical Financials'!B60/1000
A20: Transaction fees | B20: =B7*Assumptions!B7
A21: Financing fees | B21: =B14*Assumptions!B8
A22: Minimum cash funded at close | B22: =Assumptions!B9/1000
A23: Total Uses | B23: =SUM(B18:B22)
A25: Sources
A26: Existing cash swept from target balance sheet | B26: ='Historical Financials'!B61/1000
A27: New Term Loan B | B27: =B12
A28: New Senior Notes | B28: =B13
A29: Revolver draw at close (undrawn) | B29: 0
A30: Sponsor equity (plug) | B30: =B23-SUM(B26:B29)
A31: Total Sources | B31: =SUM(B26:B30)
A32: CHECK: Total Sources − Total Uses (must = 0) | B32: =B31-B23
A34: Capitalization Summary
A35: Sponsor equity / Entry TEV | B35: =B30/B7
A36: Opening net debt at close (new debt − minimum cash) | B36: =B14-B22
A37: Opening total debt / Entry EBITDA | B37: =B14/B5
A38: Opening net debt / Entry EBITDA | B38: =B36/B5

Sheet Debt Schedule
A1: V2X, Inc. (NYSE: VVX) — Debt Schedule
A2: $ in millions. Interest computed on beginning-of-year balances (documented convention; avoids circularity -- no iterative calculation needed). Average balances shown as a memo only.
B5: At Close | C5: FY2026 | D5: FY2027 | E5: FY2028 | F5: FY2029 | G5: FY2030
A7: Cash Flow Available for Debt Service
A8: Beginning cash balance | B8: ='Sources & Uses'!B22 | C8: =B8 | D8: =C39 | E8: =D39 | F8: =E39 | G8: =F39
A9: Levered FCF before debt service (CFADS) | C9: ='Free Cash Flow'!C10 | D9: ='Free Cash Flow'!D10 | E9: ='Free Cash Flow'!E10 | F9: ='Free Cash Flow'!F10 | G9: ='Free Cash Flow'!G10
A10: Less: mandatory amortization — Term Loan B | C10: =C23 | D10: =D23 | E10: =E23 | F10: =F23 | G10: =G23
A11: Less: mandatory amortization — Senior Notes (bullet) | C11: 0 | D11: 0 | E11: 0 | F11: 0 | G11: 0
A12: Cash flow before revolver activity (vs. min. cash target) | C12: =C8+C9-C10-C11-Assumptions!$B$9/1000 | D12: =D8+D9-D10-D11-Assumptions!$B$9/1000 | E12: =E8+E9-E10-E11-Assumptions!$B$9/1000 | F12: =F8+F9-F10-F11-Assumptions!$B$9/1000 | G12: =G8+G9-G10-G11-Assumptions!$B$9/1000
A14: Revolver
A15: Beginning balance | B15: ='Sources & Uses'!B29 | C15: =B15 | D15: =C17 | E15: =D17 | F15: =E17 | G15: =F17
A16: Draw / (Paydown) | C16: =IF(C12<0,-C12,-MIN(C15,MAX(0,C12))) | D16: =IF(D12<0,-D12,-MIN(D15,MAX(0,D12))) | E16: =IF(E12<0,-E12,-MIN(E15,MAX(0,E12))) | F16: =IF(F12<0,-F12,-MIN(F15,MAX(0,F12))) | G16: =IF(G12<0,-G12,-MIN(G15,MAX(0,G12)))
A17: Ending balance | C17: =C15+C16 | D17: =D15+D16 | E17: =E15+E16 | F17: =F15+F16 | G17: =G15+G16
A18: Average balance (memo only; interest uses beginning balance below) | C18: =(C15+C17)/2 | D18: =(D15+D17)/2 | E18: =(E15+E17)/2 | F18: =(F15+F17)/2 | G18: =(G15+G17)/2
A19: Interest expense on beginning balance (incl. commitment fee on undrawn) | C19: =C15*Assumptions!$B$20+(Assumptions!$B$17/1000-C15)*Assumptions!$B$21 | D19: =D15*Assumptions!$B$20+(Assumptions!$B$17/1000-D15)*Assumptions!$B$21 | E19: =E15*Assumptions!$B$20+(Assumptions!$B$17/1000-E15)*Assumptions!$B$21 | F19: =F15*Assumptions!$B$20+(Assumptions!$B$17/1000-F15)*Assumptions!$B$21 | G19: =G15*Assumptions!$B$20+(Assumptions!$B$17/1000-G15)*Assumptions!$B$21
A21: Term Loan B
A22: Beginning balance | B22: ='Sources & Uses'!B27 | C22: =B22 | D22: =C25 | E22: =D25 | F22: =E25 | G22: =F25
A23: Mandatory amortization (1.00% of original principal p.a.) | C23: =MIN(C22,Assumptions!$B$22*$B$22) | D23: =MIN(D22,Assumptions!$B$22*$B$22) | E23: =MIN(E22,Assumptions!$B$22*$B$22) | F23: =MIN(F22,Assumptions!$B$22*$B$22) | G23: =MIN(G22,Assumptions!$B$22*$B$22)
A24: Optional cash flow sweep | C24: =MIN(MAX(0,C22-C23),Assumptions!$B$23*MAX(0,C12-C15)) | D24: =MIN(MAX(0,D22-D23),Assumptions!$B$23*MAX(0,D12-D15)) | E24: =MIN(MAX(0,E22-E23),Assumptions!$B$23*MAX(0,E12-E15)) | F24: =MIN(MAX(0,F22-F23),Assumptions!$B$23*MAX(0,F12-F15)) | G24: =MIN(MAX(0,G22-G23),Assumptions!$B$23*MAX(0,G12-G15))
A25: Ending balance | C25: =C22-C23-C24 | D25: =D22-D23-D24 | E25: =E22-E23-E24 | F25: =F22-F23-F24 | G25: =G22-G23-G24
A26: Average balance (memo only; interest uses beginning balance below) | C26: =(C22+C25)/2 | D26: =(D22+D25)/2 | E26: =(E22+E25)/2 | F26: =(F22+F25)/2 | G26: =(G22+G25)/2
A27: Interest expense on beginning balance | C27: =C22*Assumptions!$B$18 | D27: =D22*Assumptions!$B$18 | E27: =E22*Assumptions!$B$18 | F27: =F22*Assumptions!$B$18 | G27: =G22*Assumptions!$B$18
A29: Senior Notes
A30: Beginning balance | B30: ='Sources & Uses'!B28 | C30: =B30 | D30: =C32 | E30: =D32 | F30: =E32 | G30: =F32
A31: Mandatory amortization (bullet at maturity) | C31: 0 | D31: 0 | E31: 0 | F31: 0 | G31: 0
A32: Ending balance | C32: =C30-C31 | D32: =D30-D31 | E32: =E30-E31 | F32: =F30-F31 | G32: =G30-G31
A33: Average balance (memo only; interest uses beginning balance below) | C33: =(C30+C32)/2 | D33: =(D30+D32)/2 | E33: =(E30+E32)/2 | F33: =(F30+F32)/2 | G33: =(G30+G32)/2
A34: Interest expense on beginning balance | C34: =C30*Assumptions!$B$19 | D34: =D30*Assumptions!$B$19 | E34: =E30*Assumptions!$B$19 | F34: =F30*Assumptions!$B$19 | G34: =G30*Assumptions!$B$19
A36: Consolidated Debt & Cash
A37: Total interest expense | C37: =C19+C27+C34 | D37: =D19+D27+D34 | E37: =E19+E27+E34 | F37: =F19+F27+F34 | G37: =G19+G27+G34
A38: Total debt outstanding, ending | B38: =B15+B22+B30 | C38: =C17+C25+C32 | D38: =D17+D25+D32 | E38: =E17+E25+E32 | F38: =F17+F25+F32 | G38: =G17+G25+G32
A39: Ending cash balance | B39: =B8 | C39: =C8+C9-C10-C11+C16-C24 | D39: =D8+D9-D10-D11+D16-D24 | E39: =E8+E9-E10-E11+E16-E24 | F39: =F8+F9-F10-F11+F16-F24 | G39: =G8+G9-G10-G11+G16-G24
A40: Total net debt, ending | B40: =B38-B39 | C40: =C38-C39 | D40: =D38-D39 | E40: =E38-E39 | F40: =F38-F39 | G40: =G38-G39
A42: CHECK: net debt at close vs. Sources & Uses opening net debt (must = 0) | B42: =B40-'Sources & Uses'!B36

Sheet Operating Model
A1: V2X, Inc. (NYSE: VVX) — Operating Model
A2: $ in millions. FY2025A shown for reference; FY2026-FY2030 are formulas off the Assumptions tab.
A4: Projected P&L
B5: FY2025A | C5: FY2026 | D5: FY2027 | E5: FY2028 | F5: FY2029 | G5: FY2030
A6: Revenue | B6: ='Historical Financials'!F10/1000 | C6: =B6*(1+Assumptions!B27) | D6: =C6*(1+Assumptions!C27) | E6: =D6*(1+Assumptions!D27) | F6: =E6*(1+Assumptions!E27) | G6: =F6*(1+Assumptions!F27)
A7: Revenue growth % | C7: =Assumptions!B27 | D7: =Assumptions!C27 | E7: =Assumptions!D27 | F7: =Assumptions!E27 | G7: =Assumptions!F27
A8: EBITDA margin % | B8: ='Historical Financials'!F55 | C8: =Assumptions!B28 | D8: =Assumptions!C28 | E8: =Assumptions!D28 | F8: =Assumptions!E28 | G8: =Assumptions!F28
A9: EBITDA | B9: ='Historical Financials'!F54/1000 | C9: =C6*C8 | D9: =D6*D8 | E9: =E6*E8 | F9: =F6*F8 | G9: =G6*G8
A10: D&A | B10: =('Historical Financials'!F46+'Historical Financials'!F47+'Historical Financials'!F48)/1000 | C10: =C6*Assumptions!$B$31 | D10: =D6*Assumptions!$B$31 | E10: =E6*Assumptions!$B$31 | F10: =F6*Assumptions!$B$31 | G10: =G6*Assumptions!$B$31
A11: EBIT | B11: =B9-B10 | C11: =C9-C10 | D11: =D9-D10 | E11: =E9-E10 | F11: =F9-F10 | G11: =G9-G10
A12: Interest expense (net) | B12: ='Historical Financials'!F15/1000 | C12: =-'Debt Schedule'!C37 | D12: =-'Debt Schedule'!D37 | E12: =-'Debt Schedule'!E37 | F12: =-'Debt Schedule'!F37 | G12: =-'Debt Schedule'!G37
A13: EBT | B13: =B11+B12 | C13: =C11+C12 | D13: =D11+D12 | E13: =E11+E12 | F13: =F11+F12 | G13: =G11+G12
A14: Taxes | B14: =MAX(0,B13)*Assumptions!$B$34 | C14: =MAX(0,C13)*Assumptions!$B$34 | D14: =MAX(0,D13)*Assumptions!$B$34 | E14: =MAX(0,E13)*Assumptions!$B$34 | F14: =MAX(0,F13)*Assumptions!$B$34 | G14: =MAX(0,G13)*Assumptions!$B$34
A15: Net income | B15: =B13-B14 | C15: =C13-C14 | D15: =D13-D14 | E15: =E13-E14 | F15: =F13-F14 | G15: =G13-G14
A17: Capex & Working Capital
A18: Capex | B18: ='Historical Financials'!F49/1000 | C18: =C6*Assumptions!$B$32 | D18: =D6*Assumptions!$B$32 | E18: =E6*Assumptions!$B$32 | F18: =F6*Assumptions!$B$32 | G18: =G6*Assumptions!$B$32
A19: Net working capital balance | B19: ='Historical Financials'!F56/1000 | C19: =C6*Assumptions!$B$33 | D19: =D6*Assumptions!$B$33 | E19: =E6*Assumptions!$B$33 | F19: =F6*Assumptions!$B$33 | G19: =G6*Assumptions!$B$33
A20: Change in NWC balance | C20: =C19-B19 | D20: =D19-C19 | E20: =E19-D19 | F20: =F19-E19 | G20: =G19-F19
A21: Cash impact from NWC (increase in NWC = cash use) | C21: =-C20 | D21: =-D20 | E21: =-E20 | F21: =-F20 | G21: =-G20

Sheet Free Cash Flow
A1: V2X, Inc. (NYSE: VVX) — Free Cash Flow
A2: $ in millions. Levered FCF available for debt paydown, feeding the Debt Schedule waterfall.
A5: Levered Free Cash Flow
A6: Net income | C6: ='Operating Model'!C15 | D6: ='Operating Model'!D15 | E6: ='Operating Model'!E15 | F6: ='Operating Model'!F15 | G6: ='Operating Model'!G15
A7: + D&A | C7: ='Operating Model'!C10 | D7: ='Operating Model'!D10 | E7: ='Operating Model'!E10 | F7: ='Operating Model'!F10 | G7: ='Operating Model'!G10
A8: − Capex | C8: ='Operating Model'!C18 | D8: ='Operating Model'!D18 | E8: ='Operating Model'!E18 | F8: ='Operating Model'!F18 | G8: ='Operating Model'!G18
A9: +/− Cash impact from NWC | C9: ='Operating Model'!C21 | D9: ='Operating Model'!D21 | E9: ='Operating Model'!E21 | F9: ='Operating Model'!F21 | G9: ='Operating Model'!G21
A10: Levered FCF before debt service (CFADS) | C10: =C6+C7-C8+C9 | D10: =D6+D7-D8+D9 | E10: =E6+E7-E8+E9 | F10: =F6+F7-F8+F9 | G10: =G6+G7-G8+G9
A12: Debt Service (from Debt Schedule)
A13: Less: mandatory amortization (TLB + Notes) | C13: ='Debt Schedule'!C10+'Debt Schedule'!C11 | D13: ='Debt Schedule'!D10+'Debt Schedule'!D11 | E13: ='Debt Schedule'!E10+'Debt Schedule'!E11 | F13: ='Debt Schedule'!F10+'Debt Schedule'!F11 | G13: ='Debt Schedule'!G10+'Debt Schedule'!G11
A14: Less: optional cash sweep (Term Loan B) | C14: ='Debt Schedule'!C24 | D14: ='Debt Schedule'!D24 | E14: ='Debt Schedule'!E24 | F14: ='Debt Schedule'!F24 | G14: ='Debt Schedule'!G24
A15: +/− Net revolver draw / (paydown) | C15: ='Debt Schedule'!C16 | D15: ='Debt Schedule'!D16 | E15: ='Debt Schedule'!E16 | F15: ='Debt Schedule'!F16 | G15: ='Debt Schedule'!G16
A16: Net change in cash | C16: =C10-C13-C14+C15 | D16: =D10-D13-D14+D15 | E16: =E10-E13-E14+E15 | F16: =F10-F13-F14+F15 | G16: =G10-G13-G14+G15
A18: CHECK: net change in cash vs. Debt Schedule roll-forward (must = 0) | C18: =C16-('Debt Schedule'!C39-'Debt Schedule'!C8) | D18: =D16-('Debt Schedule'!D39-'Debt Schedule'!D8) | E18: =E16-('Debt Schedule'!E39-'Debt Schedule'!E8) | F18: =F16-('Debt Schedule'!F39-'Debt Schedule'!F8) | G18: =G16-('Debt Schedule'!G39-'Debt Schedule'!G8)

Sheet Returns
A1: V2X, Inc. (NYSE: VVX) — Returns
A2: $ in millions except per-x and % rows.
A4: Entry (12/31/2025)
A5: Entry EBITDA | B5: ='Sources & Uses'!B5
A6: Entry multiple | B6: ='Sources & Uses'!B6
A7: Entry TEV | B7: ='Sources & Uses'!B7
A8: Sponsor equity investment | B8: ='Sources & Uses'!B30
A10: Exit (FY2030)
A11: Exit EBITDA | B11: ='Operating Model'!G9
A12: Exit multiple | B12: =Assumptions!B12
A13: Exit TEV | B13: =B11*B12
A14: Exit net debt | B14: ='Debt Schedule'!G40
A15: Exit equity value | B15: =B13-B14
A17: Sponsor Returns
A18: MOIC | B18: =B15/B8
A19: IRR | B19: =IRR(B23:G23)
A21: Cash Flow Timeline for IRR
A22: Year | B22: 0 | C22: 1 | D22: 2 | E22: 3 | F22: 4 | G22: 5
A23: Sponsor cash flow | B23: =-B8 | C23: 0 | D23: 0 | E23: 0 | F23: 0 | G23: =B15
A25: Returns Attribution — Value Creation Bridge (ties exactly to Exit Equity Value)
A26: Sponsor equity (entry) | B26: =B8
A27: + EBITDA growth (Entry multiple x change in EBITDA) | B27: =B6*(B11-B5)
A28: + Multiple expansion / (contraction) | B28: =(B12-B6)*B11
A29: + Deleveraging (opening net debt less exit net debt) | B29: ='Sources & Uses'!B36-B14
A30: − Fees & frictional costs at entry | B30: =-('Sources & Uses'!B20+'Sources & Uses'!B21)
A31: Total: Exit equity value (attribution check) | B31: =SUM(B26:B30)
A32: CHECK: attribution total − exit equity value (must = 0) | B32: =B31-B15

Sheet Sensitivities
A1: V2X, Inc. (NYSE: VVX) — Sensitivities
A2: Every cell is a live formula. Change any header (blue) to re-run the grid.
A4: Table 1 — IRR by Entry Multiple (rows) x Exit Multiple (columns)
A5: Entry \ Exit | C5: 9 | D5: 10 | E5: 11 | F5: 12 | G5: 13
B6: 9 | C6: =((C$5*'Operating Model'!$G$9-'Debt Schedule'!$G$40)/($B6*'Sources & Uses'!$B$5*(1+Assumptions!$B$7)+'Sources & Uses'!$B$21+'Sources & Uses'!$B$22-'Sources & Uses'!$B$12-'Sources & Uses'!$B$13))^(1/Assumptions!$B$10)-1 | D6: =((D$5*'Operating Model'!$G$9-'Debt Schedule'!$G$40)/($B6*'Sources & Uses'!$B$5*(1+Assumptions!$B$7)+'Sources & Uses'!$B$21+'Sources & Uses'!$B$22-'Sources & Uses'!$B$12-'Sources & Uses'!$B$13))^(1/Assumptions!$B$10)-1 | E6: =((E$5*'Operating Model'!$G$9-'Debt Schedule'!$G$40)/($B6*'Sources & Uses'!$B$5*(1+Assumptions!$B$7)+'Sources & Uses'!$B$21+'Sources & Uses'!$B$22-'Sources & Uses'!$B$12-'Sources & Uses'!$B$13))^(1/Assumptions!$B$10)-1 | F6: =((F$5*'Operating Model'!$G$9-'Debt Schedule'!$G$40)/($B6*'Sources & Uses'!$B$5*(1+Assumptions!$B$7)+'Sources & Uses'!$B$21+'Sources & Uses'!$B$22-'Sources & Uses'!$B$12-'Sources & Uses'!$B$13))^(1/Assumptions!$B$10)-1 | G6: =((G$5*'Operating Model'!$G$9-'Debt Schedule'!$G$40)/($B6*'Sources & Uses'!$B$5*(1+Assumptions!$B$7)+'Sources & Uses'!$B$21+'Sources & Uses'!$B$22-'Sources & Uses'!$B$12-'Sources & Uses'!$B$13))^(1/Assumptions!$B$10)-1
B7: 10 | C7: =((C$5*'Operating Model'!$G$9-'Debt Schedule'!$G$40)/($B7*'Sources & Uses'!$B$5*(1+Assumptions!$B$7)+'Sources & Uses'!$B$21+'Sources & Uses'!$B$22-'Sources & Uses'!$B$12-'Sources & Uses'!$B$13))^(1/Assumptions!$B$10)-1 | D7: =((D$5*'Operating Model'!$G$9-'Debt Schedule'!$G$40)/($B7*'Sources & Uses'!$B$5*(1+Assumptions!$B$7)+'Sources & Uses'!$B$21+'Sources & Uses'!$B$22-'Sources & Uses'!$B$12-'Sources & Uses'!$B$13))^(1/Assumptions!$B$10)-1 | E7: =((E$5*'Operating Model'!$G$9-'Debt Schedule'!$G$40)/($B7*'Sources & Uses'!$B$5*(1+Assumptions!$B$7)+'Sources & Uses'!$B$21+'Sources & Uses'!$B$22-'Sources & Uses'!$B$12-'Sources & Uses'!$B$13))^(1/Assumptions!$B$10)-1 | F7: =((F$5*'Operating Model'!$G$9-'Debt Schedule'!$G$40)/($B7*'Sources & Uses'!$B$5*(1+Assumptions!$B$7)+'Sources & Uses'!$B$21+'Sources & Uses'!$B$22-'Sources & Uses'!$B$12-'Sources & Uses'!$B$13))^(1/Assumptions!$B$10)-1 | G7: =((G$5*'Operating Model'!$G$9-'Debt Schedule'!$G$40)/($B7*'Sources & Uses'!$B$5*(1+Assumptions!$B$7)+'Sources & Uses'!$B$21+'Sources & Uses'!$B$22-'Sources & Uses'!$B$12-'Sources & Uses'!$B$13))^(1/Assumptions!$B$10)-1
B8: 11 | C8: =((C$5*'Operating Model'!$G$9-'Debt Schedule'!$G$40)/($B8*'Sources & Uses'!$B$5*(1+Assumptions!$B$7)+'Sources & Uses'!$B$21+'Sources & Uses'!$B$22-'Sources & Uses'!$B$12-'Sources & Uses'!$B$13))^(1/Assumptions!$B$10)-1 | D8: =((D$5*'Operating Model'!$G$9-'Debt Schedule'!$G$40)/($B8*'Sources & Uses'!$B$5*(1+Assumptions!$B$7)+'Sources & Uses'!$B$21+'Sources & Uses'!$B$22-'Sources & Uses'!$B$12-'Sources & Uses'!$B$13))^(1/Assumptions!$B$10)-1 | E8: =((E$5*'Operating Model'!$G$9-'Debt Schedule'!$G$40)/($B8*'Sources & Uses'!$B$5*(1+Assumptions!$B$7)+'Sources & Uses'!$B$21+'Sources & Uses'!$B$22-'Sources & Uses'!$B$12-'Sources & Uses'!$B$13))^(1/Assumptions!$B$10)-1 | F8: =((F$5*'Operating Model'!$G$9-'Debt Schedule'!$G$40)/($B8*'Sources & Uses'!$B$5*(1+Assumptions!$B$7)+'Sources & Uses'!$B$21+'Sources & Uses'!$B$22-'Sources & Uses'!$B$12-'Sources & Uses'!$B$13))^(1/Assumptions!$B$10)-1 | G8: =((G$5*'Operating Model'!$G$9-'Debt Schedule'!$G$40)/($B8*'Sources & Uses'!$B$5*(1+Assumptions!$B$7)+'Sources & Uses'!$B$21+'Sources & Uses'!$B$22-'Sources & Uses'!$B$12-'Sources & Uses'!$B$13))^(1/Assumptions!$B$10)-1
B9: 12 | C9: =((C$5*'Operating Model'!$G$9-'Debt Schedule'!$G$40)/($B9*'Sources & Uses'!$B$5*(1+Assumptions!$B$7)+'Sources & Uses'!$B$21+'Sources & Uses'!$B$22-'Sources & Uses'!$B$12-'Sources & Uses'!$B$13))^(1/Assumptions!$B$10)-1 | D9: =((D$5*'Operating Model'!$G$9-'Debt Schedule'!$G$40)/($B9*'Sources & Uses'!$B$5*(1+Assumptions!$B$7)+'Sources & Uses'!$B$21+'Sources & Uses'!$B$22-'Sources & Uses'!$B$12-'Sources & Uses'!$B$13))^(1/Assumptions!$B$10)-1 | E9: =((E$5*'Operating Model'!$G$9-'Debt Schedule'!$G$40)/($B9*'Sources & Uses'!$B$5*(1+Assumptions!$B$7)+'Sources & Uses'!$B$21+'Sources & Uses'!$B$22-'Sources & Uses'!$B$12-'Sources & Uses'!$B$13))^(1/Assumptions!$B$10)-1 | F9: =((F$5*'Operating Model'!$G$9-'Debt Schedule'!$G$40)/($B9*'Sources & Uses'!$B$5*(1+Assumptions!$B$7)+'Sources & Uses'!$B$21+'Sources & Uses'!$B$22-'Sources & Uses'!$B$12-'Sources & Uses'!$B$13))^(1/Assumptions!$B$10)-1 | G9: =((G$5*'Operating Model'!$G$9-'Debt Schedule'!$G$40)/($B9*'Sources & Uses'!$B$5*(1+Assumptions!$B$7)+'Sources & Uses'!$B$21+'Sources & Uses'!$B$22-'Sources & Uses'!$B$12-'Sources & Uses'!$B$13))^(1/Assumptions!$B$10)-1
B10: 13 | C10: =((C$5*'Operating Model'!$G$9-'Debt Schedule'!$G$40)/($B10*'Sources & Uses'!$B$5*(1+Assumptions!$B$7)+'Sources & Uses'!$B$21+'Sources & Uses'!$B$22-'Sources & Uses'!$B$12-'Sources & Uses'!$B$13))^(1/Assumptions!$B$10)-1 | D10: =((D$5*'Operating Model'!$G$9-'Debt Schedule'!$G$40)/($B10*'Sources & Uses'!$B$5*(1+Assumptions!$B$7)+'Sources & Uses'!$B$21+'Sources & Uses'!$B$22-'Sources & Uses'!$B$12-'Sources & Uses'!$B$13))^(1/Assumptions!$B$10)-1 | E10: =((E$5*'Operating Model'!$G$9-'Debt Schedule'!$G$40)/($B10*'Sources & Uses'!$B$5*(1+Assumptions!$B$7)+'Sources & Uses'!$B$21+'Sources & Uses'!$B$22-'Sources & Uses'!$B$12-'Sources & Uses'!$B$13))^(1/Assumptions!$B$10)-1 | F10: =((F$5*'Operating Model'!$G$9-'Debt Schedule'!$G$40)/($B10*'Sources & Uses'!$B$5*(1+Assumptions!$B$7)+'Sources & Uses'!$B$21+'Sources & Uses'!$B$22-'Sources & Uses'!$B$12-'Sources & Uses'!$B$13))^(1/Assumptions!$B$10)-1 | G10: =((G$5*'Operating Model'!$G$9-'Debt Schedule'!$G$40)/($B10*'Sources & Uses'!$B$5*(1+Assumptions!$B$7)+'Sources & Uses'!$B$21+'Sources & Uses'!$B$22-'Sources & Uses'!$B$12-'Sources & Uses'!$B$13))^(1/Assumptions!$B$10)-1
A13: Table 2 — IRR by Exit Multiple (rows) x 5-Yr Revenue CAGR (columns)
A14: Simplification: aggregate (non-tranche) debt paydown; interest expense held at base-case $ (2nd-order effect of paydown speed on interest is not re-derived per scenario); same margin/capex/NWC/tax assumptions as base case. See helper block below.
A15: Exit Mult \ CAGR | C15: 0.02 | D15: 0.03 | E15: 0.043 | F15: 0.055 | G15: 0.07
B16: 9 | C16: =(($B16*G27-(G34-G36))/'Sources & Uses'!$B$30)^(1/Assumptions!$B$10)-1 | D16: =(($B16*G41-(G48-G50))/'Sources & Uses'!$B$30)^(1/Assumptions!$B$10)-1 | E16: =(($B16*G55-(G62-G64))/'Sources & Uses'!$B$30)^(1/Assumptions!$B$10)-1 | F16: =(($B16*G69-(G76-G78))/'Sources & Uses'!$B$30)^(1/Assumptions!$B$10)-1 | G16: =(($B16*G83-(G90-G92))/'Sources & Uses'!$B$30)^(1/Assumptions!$B$10)-1
B17: 10 | C17: =(($B17*G27-(G34-G36))/'Sources & Uses'!$B$30)^(1/Assumptions!$B$10)-1 | D17: =(($B17*G41-(G48-G50))/'Sources & Uses'!$B$30)^(1/Assumptions!$B$10)-1 | E17: =(($B17*G55-(G62-G64))/'Sources & Uses'!$B$30)^(1/Assumptions!$B$10)-1 | F17: =(($B17*G69-(G76-G78))/'Sources & Uses'!$B$30)^(1/Assumptions!$B$10)-1 | G17: =(($B17*G83-(G90-G92))/'Sources & Uses'!$B$30)^(1/Assumptions!$B$10)-1
B18: 11 | C18: =(($B18*G27-(G34-G36))/'Sources & Uses'!$B$30)^(1/Assumptions!$B$10)-1 | D18: =(($B18*G41-(G48-G50))/'Sources & Uses'!$B$30)^(1/Assumptions!$B$10)-1 | E18: =(($B18*G55-(G62-G64))/'Sources & Uses'!$B$30)^(1/Assumptions!$B$10)-1 | F18: =(($B18*G69-(G76-G78))/'Sources & Uses'!$B$30)^(1/Assumptions!$B$10)-1 | G18: =(($B18*G83-(G90-G92))/'Sources & Uses'!$B$30)^(1/Assumptions!$B$10)-1
B19: 12 | C19: =(($B19*G27-(G34-G36))/'Sources & Uses'!$B$30)^(1/Assumptions!$B$10)-1 | D19: =(($B19*G41-(G48-G50))/'Sources & Uses'!$B$30)^(1/Assumptions!$B$10)-1 | E19: =(($B19*G55-(G62-G64))/'Sources & Uses'!$B$30)^(1/Assumptions!$B$10)-1 | F19: =(($B19*G69-(G76-G78))/'Sources & Uses'!$B$30)^(1/Assumptions!$B$10)-1 | G19: =(($B19*G83-(G90-G92))/'Sources & Uses'!$B$30)^(1/Assumptions!$B$10)-1
B20: 13 | C20: =(($B20*G27-(G34-G36))/'Sources & Uses'!$B$30)^(1/Assumptions!$B$10)-1 | D20: =(($B20*G41-(G48-G50))/'Sources & Uses'!$B$30)^(1/Assumptions!$B$10)-1 | E20: =(($B20*G55-(G62-G64))/'Sources & Uses'!$B$30)^(1/Assumptions!$B$10)-1 | F20: =(($B20*G69-(G76-G78))/'Sources & Uses'!$B$30)^(1/Assumptions!$B$10)-1 | G20: =(($B20*G83-(G90-G92))/'Sources & Uses'!$B$30)^(1/Assumptions!$B$10)-1
A23: Sensitivity Helper — Simplified 5-Year Roll-Forward by Revenue CAGR Scenario (feeds Table 2)
A24: Scenario 1: Revenue CAGR = C15
C25: FY2026 | D25: FY2027 | E25: FY2028 | F25: FY2029 | G25: FY2030
A26: Revenue | B26: ='Historical Financials'!F10/1000 | C26: =B26*(1+$C$15) | D26: =C26*(1+$C$15) | E26: =D26*(1+$C$15) | F26: =E26*(1+$C$15) | G26: =F26*(1+$C$15)
A27: EBITDA | C27: =C26*Assumptions!B28 | D27: =D26*Assumptions!C28 | E27: =E26*Assumptions!D28 | F27: =F26*Assumptions!E28 | G27: =G26*Assumptions!F28
A28: D&A | C28: =C26*Assumptions!$B$31 | D28: =D26*Assumptions!$B$31 | E28: =E26*Assumptions!$B$31 | F28: =F26*Assumptions!$B$31 | G28: =G26*Assumptions!$B$31
A29: EBT (interest held at base-case $) | C29: =C27-C28-'Debt Schedule'!C37 | D29: =D27-D28-'Debt Schedule'!D37 | E29: =E27-E28-'Debt Schedule'!E37 | F29: =F27-F28-'Debt Schedule'!F37 | G29: =G27-G28-'Debt Schedule'!G37
A30: Net income | C30: =C29-MAX(0,C29)*Assumptions!$B$34 | D30: =D29-MAX(0,D29)*Assumptions!$B$34 | E30: =E29-MAX(0,E29)*Assumptions!$B$34 | F30: =F29-MAX(0,F29)*Assumptions!$B$34 | G30: =G29-MAX(0,G29)*Assumptions!$B$34
A31: FCF before debt service | C31: =C30+C28-C26*Assumptions!$B$32-(C26-B26)*Assumptions!$B$33 | D31: =D30+D28-D26*Assumptions!$B$32-(D26-C26)*Assumptions!$B$33 | E31: =E30+E28-E26*Assumptions!$B$32-(E26-D26)*Assumptions!$B$33 | F31: =F30+F28-F26*Assumptions!$B$32-(F26-E26)*Assumptions!$B$33 | G31: =G30+G28-G26*Assumptions!$B$32-(G26-F26)*Assumptions!$B$33
A32: Debt, beginning | B32: ='Sources & Uses'!B14 | C32: =B32 | D32: =C34 | E32: =D34 | F32: =E34 | G32: =F34
A33: Mandatory amort. + sweep | C33: =MIN(MAX(0,C32-'Debt Schedule'!C23),'Debt Schedule'!C23+Assumptions!$B$23*MAX(0,C31-'Debt Schedule'!C23)) | D33: =MIN(MAX(0,D32-'Debt Schedule'!D23),'Debt Schedule'!D23+Assumptions!$B$23*MAX(0,D31-'Debt Schedule'!D23)) | E33: =MIN(MAX(0,E32-'Debt Schedule'!E23),'Debt Schedule'!E23+Assumptions!$B$23*MAX(0,E31-'Debt Schedule'!E23)) | F33: =MIN(MAX(0,F32-'Debt Schedule'!F23),'Debt Schedule'!F23+Assumptions!$B$23*MAX(0,F31-'Debt Schedule'!F23)) | G33: =MIN(MAX(0,G32-'Debt Schedule'!G23),'Debt Schedule'!G23+Assumptions!$B$23*MAX(0,G31-'Debt Schedule'!G23))
A34: Debt, ending | C34: =C32-C33 | D34: =D32-D33 | E34: =E32-E33 | F34: =F32-F33 | G34: =G32-G33
A35: Cash, beginning | B35: =Assumptions!$B$9/1000 | C35: =B35 | D35: =C36 | E35: =D36 | F35: =E36 | G35: =F36
A36: Cash, ending | C36: =C35+C31-C33 | D36: =D35+D31-D33 | E36: =E35+E31-E33 | F36: =F35+F31-F33 | G36: =G35+G31-G33
A38: Scenario 2: Revenue CAGR = D15
C39: FY2026 | D39: FY2027 | E39: FY2028 | F39: FY2029 | G39: FY2030
A40: Revenue | B40: ='Historical Financials'!F10/1000 | C40: =B40*(1+$D$15) | D40: =C40*(1+$D$15) | E40: =D40*(1+$D$15) | F40: =E40*(1+$D$15) | G40: =F40*(1+$D$15)
A41: EBITDA | C41: =C40*Assumptions!B28 | D41: =D40*Assumptions!C28 | E41: =E40*Assumptions!D28 | F41: =F40*Assumptions!E28 | G41: =G40*Assumptions!F28
A42: D&A | C42: =C40*Assumptions!$B$31 | D42: =D40*Assumptions!$B$31 | E42: =E40*Assumptions!$B$31 | F42: =F40*Assumptions!$B$31 | G42: =G40*Assumptions!$B$31
A43: EBT (interest held at base-case $) | C43: =C41-C42-'Debt Schedule'!C37 | D43: =D41-D42-'Debt Schedule'!D37 | E43: =E41-E42-'Debt Schedule'!E37 | F43: =F41-F42-'Debt Schedule'!F37 | G43: =G41-G42-'Debt Schedule'!G37
A44: Net income | C44: =C43-MAX(0,C43)*Assumptions!$B$34 | D44: =D43-MAX(0,D43)*Assumptions!$B$34 | E44: =E43-MAX(0,E43)*Assumptions!$B$34 | F44: =F43-MAX(0,F43)*Assumptions!$B$34 | G44: =G43-MAX(0,G43)*Assumptions!$B$34
A45: FCF before debt service | C45: =C44+C42-C40*Assumptions!$B$32-(C40-B40)*Assumptions!$B$33 | D45: =D44+D42-D40*Assumptions!$B$32-(D40-C40)*Assumptions!$B$33 | E45: =E44+E42-E40*Assumptions!$B$32-(E40-D40)*Assumptions!$B$33 | F45: =F44+F42-F40*Assumptions!$B$32-(F40-E40)*Assumptions!$B$33 | G45: =G44+G42-G40*Assumptions!$B$32-(G40-F40)*Assumptions!$B$33
A46: Debt, beginning | B46: ='Sources & Uses'!B14 | C46: =B46 | D46: =C48 | E46: =D48 | F46: =E48 | G46: =F48
...

Sheet Credit Stats
A1: V2X, Inc. (NYSE: VVX) — Credit Stats
A2: $ in millions. Shows whether the LBO capital structure is financeable across the hold.
B4: At Close | C4: FY2026 | D4: FY2027 | E4: FY2028 | F4: FY2029 | G4: FY2030
A5: Total debt outstanding | B5: ='Debt Schedule'!B38 | C5: ='Debt Schedule'!C38 | D5: ='Debt Schedule'!D38 | E5: ='Debt Schedule'!E38 | F5: ='Debt Schedule'!F38 | G5: ='Debt Schedule'!G38
A6: Net debt | B6: ='Debt Schedule'!B40 | C6: ='Debt Schedule'!C40 | D6: ='Debt Schedule'!D40 | E6: ='Debt Schedule'!E40 | F6: ='Debt Schedule'!F40 | G6: ='Debt Schedule'!G40
A7: EBITDA | B7: ='Sources & Uses'!B5 | C7: ='Operating Model'!C9 | D7: ='Operating Model'!D9 | E7: ='Operating Model'!E9 | F7: ='Operating Model'!F9 | G7: ='Operating Model'!G9
A8: Total interest expense | B8: n/a | C8: ='Debt Schedule'!C37 | D8: ='Debt Schedule'!D37 | E8: ='Debt Schedule'!E37 | F8: ='Debt Schedule'!F37 | G8: ='Debt Schedule'!G37
A10: Total Debt / EBITDA | B10: =B5/B7 | C10: =C5/C7 | D10: =D5/D7 | E10: =E5/E7 | F10: =F5/F7 | G10: =G5/G7
A11: Net Debt / EBITDA | B11: =B6/B7 | C11: =C6/C7 | D11: =D6/D7 | E11: =E6/E7 | F11: =F6/F7 | G11: =G6/G7
A12: EBITDA / Interest expense | B12: n/a | C12: =C7/C8 | D12: =D7/D8 | E12: =E7/E8 | F12: =F7/F8 | G12: =G7/G8
